Workbook

Sheet Сводка
A1: Баня 5×4 с мансардой — бюджет по этапам строительства
A3: Учитывать работы подрядчика (1 — да, 0 — строим сами) | B3: 1
A4: Резерв на непредвиденное | B4: 0.1
A6: Код | B6: Этап | C6: Материалы, ₽ | D6: Работы подрядчика, ₽ | E6: Итого по этапу, ₽ | F6: Доля | G6: Нарастающим итогом, ₽ | H6: Срок, нед. | I6: Месяц оплаты (план)
A7: Э1 | B7: Подготовка участка и подвод сетей | C7: =SUMIF(Смета!$A$5:$A$107,A7,Смета!$F$5:$F$107) -> 102600 | D7: 25000 | E7: =C7+D7*$B$3 -> 127600 | F7: =IF($E$21=0,0,E7/$E$21) -> 0.057829561 | G7: =SUM($E$7:E7) -> 127600 | H7: 1 | I7: мес. 1
A8: Э2 | B8: Свайное поле: сваи 2,5 м | C8: =SUMIF(Смета!$A$5:$A$107,A8,Смета!$F$5:$F$107) -> 93000 | D8: 0 | E8: =C8+D8*$B$3 -> 93000 | F8: =IF($E$21=0,0,E8/$E$21) -> 0.042148504 | G8: =SUM($E$7:E8) -> 220600 | H8: 0.5 | I8: мес. 1
A9: Э3 | B9: Ростверк и черновой пол | C9: =SUMIF(Смета!$A$5:$A$107,A9,Смета!$F$5:$F$107) -> 112620 | D9: 45000 | E9: =C9+D9*$B$3 -> 157620 | F9: =IF($E$21=0,0,E9/$E$21) -> 0.071434916 | G9: =SUM($E$7:E9) -> 378220 | H9: 1 | I9: мес. 2
A10: Э4 | B10: Каркас стен 1 этажа и перегородки | C10: =SUMIF(Смета!$A$5:$A$107,A10,Смета!$F$5:$F$107) -> 68770 | D10: 60000 | E10: =C10+D10*$B$3 -> 128770 | F10: =IF($E$21=0,0,E10/$E$21) -> 0.058359816 | G10: =SUM($E$7:E10) -> 506990 | H10: 1 | I10: мес. 2
A11: Э5 | B11: Перекрытие (пол мансарды) | C11: =SUMIF(Смета!$A$5:$A$107,A11,Смета!$F$5:$F$107) -> 85796 | D11: 35000 | E11: =C11+D11*$B$3 -> 120796 | F11: =IF($E$21=0,0,E11/$E$21) -> 0.054745922 | G11: =SUM($E$7:E11) -> 627786 | H11: 0.5 | I11: мес. 3
A12: Э6 | B12: Каркас стен 2 этажа: колени и фронтоны | C12: =SUMIF(Смета!$A$5:$A$107,A12,Смета!$F$5:$F$107) -> 22440 | D12: 40000 | E12: =C12+D12*$B$3 -> 62440 | F12: =IF($E$21=0,0,E12/$E$21) -> 0.028298415 | G12: =SUM($E$7:E12) -> 690226 | H12: 0.5 | I12: мес. 3
A13: Э7 | B13: Коньковая балка | C13: =SUMIF(Смета!$A$5:$A$107,A13,Смета!$F$5:$F$107) -> 21040 | D13: 8000 | E13: =C13+D13*$B$3 -> 29040 | F13: =IF($E$21=0,0,E13/$E$21) -> 0.01316121 | G13: =SUM($E$7:E13) -> 719266 | H13: 0.3 | I13: мес. 4
A14: Э8 | B14: Стропила и кровля из профнастила | C14: =SUMIF(Смета!$A$5:$A$107,A14,Смета!$F$5:$F$107) -> 123100 | D14: 80000 | E14: =C14+D14*$B$3 -> 203100 | F14: =IF($E$21=0,0,E14/$E$21) -> 0.092046895 | G14: =SUM($E$7:E14) -> 922366 | H14: 1.5 | I14: мес. 4
A15: Э9 | B15: Окна и двери (закрытие контура) | C15: =SUMIF(Смета!$A$5:$A$107,A15,Смета!$F$5:$F$107) -> 158000 | D15: 25000 | E15: =C15+D15*$B$3 -> 183000 | F15: =IF($E$21=0,0,E15/$E$21) -> 0.082937379 | G15: =SUM($E$7:E15) -> 1105366 | H15: 0.5 | I15: мес. 5
A16: Э10 | B16: Утепление, защита, обшивка, полы мокрой зоны | C16: =SUMIF(Смета!$A$5:$A$107,A16,Смета!$F$5:$F$107) -> 428050 | D16: 140000 | E16: =C16+D16*$B$3 -> 568050 | F16: =IF($E$21=0,0,E16/$E$21) -> 0.25744578 | G16: =SUM($E$7:E16) -> 1673416 | H16: 3 | I16: мес. 5
A17: Э11 | B17: Печь и дымоход Ø115 | C17: =SUMIF(Смета!$A$5:$A$107,A17,Смета!$F$5:$F$107) -> 133650 | D17: 25000 | E17: =C17+D17*$B$3 -> 158650 | F17: =IF($E$21=0,0,E17/$E$21) -> 0.071901722 | G17: =SUM($E$7:E17) -> 1832066 | H17: 0.5 | I17: мес. 6
A18: Э12 | B18: Лестница (металл + дерево) | C18: =SUMIF(Смета!$A$5:$A$107,A18,Смета!$F$5:$F$107) -> 30260 | D18: 45000 | E18: =C18+D18*$B$3 -> 75260 | F18: =IF($E$21=0,0,E18/$E$21) -> 0.034108564 | G18: =SUM($E$7:E18) -> 1907326 | H18: 1 | I18: мес. 6
... A20: Э14 | B20: Терраса под навесом | C20: =SUMIF(Смета!$A$5:$A$107,A20,Смета!$F$5:$F$107) -> 95158 | D20: 60000 | E20: =C20+D20*$B$3 -> 155158 | F20: =IF($E$21=0,0,E20/$E$21) -> 0.070319114 | G20: =SUM($E$7:E20) -> 2206484 | H20: 1 | I20: мес. 7
B21: Итого по этапам | C21: =SUM(C7:C20) -> 1558484 | D21: =SUM(D7:D20) -> 648000 | E21: =SUM(E7:E20) -> 2206484 | H21: =SUM(H7:H20) -> 13.3
B22: Резерв на непредвиденное | E22: =E21*$B$4 -> 220648.4
B23: ВСЕГО с резервом | E23: =E21+E22 -> 2427132.4
B24: Только материалы (строим сами) + резерв | E24: =C21*(1+$B$4) -> 1714332.4
A26: Цены — ориентир на октябрь 2026 (СПб и Ленобласть): пиломатериал естественной влажности 16 500–20 000 ₽/м³, сваи Ø108×2500 3 100–4 000 ₽ по данным поставщиков; сухая калиброванная доска принята 30 000–35 000 ₽/м³; остальное — оценка. Уточните цены у своих поставщиков в листе «Смета».
A27: Работы подрядчика — ориентировочные суммы; если строите сами, поставьте 0 в ячейке B3. Сроки — при бригаде 2–4 человека, без простоев и доставки.

Sheet Пиломатериал
A1: Пиломатериал по этапам — из модели каркаса (альбом вер.33)
A2: Запас на отходы | B2: 0.1
A4: Этап | B4: Сечение | C4: Деталей, шт. | D4: Пог. м | E4: Объём по модели, м³ | F4: С запасом, м³
A5: Э3 | B5: 50×150 | C5: 72 | D5: 187.2 | E5: 1.404 | F5: =ROUND(E5*(1+$B$2),3) -> 1.544
A6: Э4 | B6: 50×100 | C6: 182 | D6: 338.1 | E6: 1.69 | F6: =ROUND(E6*(1+$B$2),3) -> 1.859
A7: Э5 | B7: 50×250 | C7: 55 | D7: 133 | E7: 1.662 | F7: =ROUND(E7*(1+$B$2),3) -> 1.828
A8: Э6 | B8: 50×100 | C8: 68 | D8: 104.2 | E8: 0.521 | F8: =ROUND(E8*(1+$B$2),3) -> 0.573
A9: Э7 | B9: 50×300 | C9: 4 | D9: 18.4 | E9: 0.276 | F9: =ROUND(E9*(1+$B$2),3) -> 0.304
A10: Э8 | B10: 50×100 | C10: 4 | D10: 22 | E10: 0.11 | F10: =ROUND(E10*(1+$B$2),3) -> 0.121
A11: Э8 | B11: 50×250 | C11: 27 | D11: 106.9 | E11: 1.336 | F11: =ROUND(E11*(1+$B$2),3) -> 1.47
A12: Итого | E12: =SUM(E5:E11) -> 6.999 | F12: =SUM(F5:F11) -> 7.699
A14: Количество деталей, длины и объёмы взяты из модели каркаса (синий шрифт — исходные данные). Запас меняется в ячейке B2.

Sheet Смета
A1: Смета материалов по этапам (цены — ориентир, октябрь 2026, СПб/ЛО)
A2: Жёлтые ячейки (количество и цена) можно менять — суммы и сводка пересчитаются.
A4: Этап | B4: Позиция | C4: Ед. | D4: Кол-во | E4: Цена за ед., ₽ | F4: Сумма, ₽ | G4: Примечание / источник
A5: Э1 | B5: Расчистка площадки, снятие растительного слоя, планировка 6×5 м | C5: компл. | D5: 1 | E5: 15000 | F5: =D5*E5 -> 15000 | G5: оценка
A6: Э1 | B6: Отводная канава для стоков (копка) | C6: м | D6: 20 | E6: 600 | F6: =D6*E6 -> 12000 | G6: длину уточнить по участку
A7: Э1 | B7: Труба ПП/ПНД 110 для выпуска стоков | C7: м | D7: 20 | E7: 450 | F7: =D7*E7 -> 9000 | G7: оценка
A8: Э1 | B8: Щебень/песок для канавы и выпуска | C8: м³ | D8: 2 | E8: 1800 | F8: =D8*E8 -> 3600 | G8: оценка
A9: Э1 | B9: Траншея под воду (ниже промерзания или с греющим кабелем) | C9: м | D9: 20 | E9: 500 | F9: =D9*E9 -> 10000 | G9: длину уточнить
A10: Э1 | B10: Труба ПЭ32 для ввода воды | C10: м | D10: 20 | E10: 120 | F10: =D10*E10 -> 2400 | G10: оценка
A11: Э1 | B11: Греющий кабель для трубы | C11: м | D11: 20 | E11: 900 | F11: =D11*E11 -> 18000 | G11: оценка
A12: Э1 | B12: Утеплитель трубы (скорлупа/трубная изоляция) | C12: м | D12: 20 | E12: 250 | F12: =D12*E12 -> 5000 | G12: оценка
A13: Э1 | B13: Фитинги, кран, гильзы | C13: компл. | D13: 1 | E13: 3000 | F13: =D13*E13 -> 3000 | G13: оценка
A14: Э1 | B14: Кабель ввода ВВГнг 3×6 в трубе ПНД | C14: м | D14: 30 | E14: 420 | F14: =D14*E14 -> 12600 | G14: длину уточнить; мощность по ТУ СНТ
A15: Э1 | B15: Щит ввода с автоматом и счётчиком (временный) | C15: компл. | D15: 1 | E15: 12000 | F15: =D15*E15 -> 12000 | G15: оценка
A16: Э2 | B16: Свая винтовая Ø108×2500 (стенка 4 мм) | C16: шт. | D16: 14 | E16: 3600 | F16: =D16*E16 -> 50400 | G16: поставщики 2026: 3 100–4 000 ₽
... A19: Э2 | B19: Антикоррозионная защита голов | C19: компл. | D19: 1 | E19: 2000 | F19: =D19*E19 -> 2000 | G19: оценка
A20: Э3 | B20: Доска 50×150 сух. (ростверк, обвязка ОН, лаги, блоки) | C20: м³ | D20: =Пиломатериал!F5 -> 1.544 | E20: 30000 | F20: =D20*E20 -> 46320 | G20: объём из модели + 10 %
A21: Э3 | B21: Шпильки M12 с гайками и шайбами 50×50×4 | C21: шт. | D21: 40 | E21: 150 | F21: =D21*E21 -> 6000 | G21: оценка
A22: Э3 | B22: Подвесы и уголки оцинкованные | C22: шт. | D22: 40 | E22: 60 | F22: =D22*E22 -> 2400 | G22: оценка
A23: Э3 | B23: Гидроизоляционная лента на оголовки | C23: рул. | D23: 1 | E23: 1500 | F23: =D23*E23 -> 1500 | G23: оценка
A24: Э3 | B24: Антисептик | C24: л | D24: 20 | E24: 350 | F24: =D24*E24 -> 7000 | G24: оценка
A25: Э3 | B25: Черновая обрешётка 100×22 под лагами | C25: м³ | D25: 0.25 | E25: 25000 | F25: =D25*E25 -> 6250 | G25: оценка
A26: Э3 | B26: Мембрана ветро-влагозащитная (пол) | C26: м² | D26: 25 | E26: 90 | F26: =D26*E26 -> 2250 | G26: оценка
A27: Э3 | B27: Минвата 150 мм (пол) | C27: м³ | D27: 2.8 | E27: 4500 | F27: =D27*E27 -> 12600 | G27: оценка
A28: Э3 | B28: Фольга / паробарьер и скотч | C28: м² | D28: 25 | E28: 80 | F28: =D28*E28 -> 2000 | G28: оценка
A29: Э3 | B29: Фанера ФСФ 22 шпунт 1220×2440 (настил пола) | C29: лист | D29: 9 | E29: 2700 | F29: =D29*E29 -> 24300 | G29: оценка
A30: Э3 | B30: Саморезы и гвозди | C30: кг | D30: 4 | E30: 500 | F30: =D30*E30 -> 2000 | G30: оценка
A31: Э4 | B31: Доска 50×100 сух. (стены 1 этажа и перегородки) | C31: м³ | D31: =Пиломатериал!F6 -> 1.859 | E31: 30000 | F31: =D31*E31 -> 55770 | G31: объём из модели + 10 %
A32: Э4 | B32: Анкеры M12 нижней обвязки | C32: шт. | D32: 30 | E32: 200 | F32: =D32*E32 -> 6000 | G32: оценка
A33: Э4 | B33: Гвозди и саморезы | C33: кг | D33: 10 | E33: 450 | F33: =D33*E33 -> 4500 | G33: оценка
A34: Э4 | B34: Уголки, пластины | C34: шт. | D34: 50 | E34: 50 | F34: =D34*E34 -> 2500 | G34: оценка
A35: Э5 | B35: Доска 50×250 сух. (лаги мансарды, ОП, тримеры, ригели) | C35: м³ | D35: =Пиломатериал!F7 -> 1.828 | E35: 32000 | F35: =D35*E35 -> 58496 | G35: объём из модели + 10 %
A36: Э5 | B36: Фанера ФСФ 22 шпунт (настил мансарды) | C36: лист | D36: 8 | E36: 2700 | F36: =D36*E36 -> 21600 | G36: оценка
A37: Э5 | B37: Уголки и подвесы | C37: шт. | D37: 60 | E37: 70 | F37: =D37*E37 -> 4200 | G37: оценка
A38: Э5 | B38: Саморезы | C38: кг | D38: 3 | E38: 500 | F38: =D38*E38 -> 1500 | G38: оценка
A39: Э6 | B39: Доска 50×100 сух. (колени, фронтоны, пакеты ПФ) | C39: м³ | D39: =Пиломатериал!F8 -> 0.573 | E39: 30000 | F39: =D39*E39 -> 17190 | G39: объём из модели + 10 %
A40: Э6 | B40: Ленты и ершики (колено → ОП → стены) | C40: шт. | D40: 20 | E40: 150 | F40: =D40*E40 -> 3000 | G40: оценка
A41: Э6 | B41: Крепёж | C41: кг | D41: 5 | E41: 450 | F41: =D41*E41 -> 2250 | G41: оценка
A42: Э7 | B42: Доска 50×300×6000 сорт 1, прямослойная (КП) | C42: м³ | D42: =Пиломатериал!F9 -> 0.304 | E42: 35000 | F42: =D42*E42 -> 10640 | G42: 4 доски, резать в 4600
A43: Э7 | B43: Шпильки M12×250 с гайками и шайбами 50×50×4 | C43: шт. | D43: 24 | E43: 250 | F43: =D43*E43 -> 6000 | G43: оценка
...

Sheet Пояснения
A1: Как пользоваться
A2: • Жёлтые ячейки — исходные данные: количество, цены, работы подрядчика, сроки, месяц оплаты. Остальное считается формулами.
A3: • Сводка!B3 = 1 — учитывать работы подрядчика; 0 — только материалы (строите сами). Сводка!B4 — резерв на непредвиденное.
A4: • Синий шрифт — введённые числа; зелёный — ссылки на другой лист; чёрный — формулы.
A5: • Пиломатериал считается из модели каркаса (альбом вер.33): объём по этапам + запас (Пиломатериал!B2).
A7: Источники цен (октябрь 2026, ориентир)
A8: • Доска обрезная естественной влажности 50×100/150/200: 16 500–20 000 ₽/м³ (карточки поставщиков 2026).
A9: • Свая винтовая Ø108×2500, стенка 4 мм: 3 100–4 000 ₽ за шт. (карточки производителей 2026).
A10: • Остальные позиции — оценка; перед закупкой уточните у поставщиков и в магазинах.
A12: Состав этапов — см. PDF «баня. этапы строительства вер.1».
